<sdf version='1.7'>
  <world name='default'>
    <light name='sun' type='directional'>
      <cast_shadows>1</cast_shadows>
      <pose>0 0 10 0 -0 0</pose>
      <diffuse>0.8 0.8 0.8 1</diffuse>
      <specular>0.2 0.2 0.2 1</specular>
      <attenuation>
        <range>1000</range>
        <constant>0.9</constant>
        <linear>0.01</linear>
        <quadratic>0.001</quadratic>
      </attenuation>
      <direction>-0.5 0.1 -0.9</direction>
      <spot>
        <inner_angle>0</inner_angle>
        <outer_angle>0</outer_angle>
        <falloff>0</falloff>
      </spot>
    </light>
    <gravity>0 0 -9.8</gravity>
    <magnetic_field>6e-06 2.3e-05 -4.2e-05</magnetic_field>
    <atmosphere type='adiabatic'/>
    <physics type='ode'>
      <max_step_size>0.001</max_step_size>
      <real_time_factor>1</real_time_factor>
      <real_time_update_rate>1000</real_time_update_rate>
    </physics>
    <scene>
      <ambient>0.4 0.4 0.4 1</ambient>
      <background>0.7 0.7 0.7 1</background>
      <shadows>1</shadows>
    </scene>
    <wind/>
    <spherical_coordinates>
      <surface_model>EARTH_WGS84</surface_model>
      <latitude_deg>0</latitude_deg>
      <longitude_deg>0</longitude_deg>
      <elevation>0</elevation>
      <heading_deg>0</heading_deg>
    </spherical_coordinates>
    <model name='Construction Cone_0'>
      <link name='link'>
        <collision name='collision'>
          <geometry>
            <mesh>
              <scale>10 10 10</scale>
              <uri>model://construction_cone/meshes/construction_cone.dae</uri>
            </mesh>
          </geometry>
          <max_contacts>10</max_contacts>
          <surface>
            <contact>
              <ode/>
            </contact>
            <bounce/>
            <friction>
              <torsional>
                <ode/>
              </torsional>
              <ode/>
            </friction>
          </surface>
        </collision>
        <visual name='visual'>
          <geometry>
            <mesh>
              <scale>10 10 10</scale>
              <uri>model://construction_cone/meshes/construction_cone.dae</uri>
            </mesh>
          </geometry>
        </visual>
        <self_collide>0</self_collide>
        <inertial>
          <pose>0 0 0 0 -0 0</pose>
          <inertia>
            <ixx>1</ixx>
            <ixy>0</ixy>
            <ixz>0</ixz>
            <iyy>1</iyy>
            <iyz>0</iyz>
            <izz>1</izz>
          </inertia>
          <mass>1</mass>
        </inertial>
        <enable_wind>0</enable_wind>
        <kinematic>0</kinematic>
      </link>
      <pose>7.6056 -1.64129 0 0 -0 0</pose>
    </model>
    <state world_name='default'>
      <sim_time>9370 421000000</sim_time>
      <real_time>75 249554419</real_time>
      <wall_time>1751839070 707138946</wall_time>
      <iterations>74898</iterations>
      <model name='Construction Cone_0'>
        <pose>1.88666 6.95718 0.05 -0 2e-06 -2.18941</pose>
        <scale>1 1 1</scale>
        <link name='link'>
          <pose>1.88666 6.95718 0.05 -0 2e-06 -2.18941</pose>
          <velocity>0 0 0 0 -0 0</velocity>
          <acceleration>0 -1e-06 -1.01965 2.49759 0.932314 0</acceleration>
          <wrench>0 -1e-06 -1.01965 0 -0 0</wrench>
        </link>
      </model>
      <model name='Construction Cone_0_clone'>
        <pose>1.7731 -0.446746 0.049992 4e-06 -3e-06 -2.03492</pose>
        <scale>1 1 1</scale>
        <link name='link'>
          <pose>1.7731 -0.446746 0.049992 4e-06 -3e-06 -2.03492</pose>
          <velocity>0 0 0 0 -0 0</velocity>
          <acceleration>0 0 -9.8 0 -0 0</acceleration>
          <wrench>0 0 -9.8 0 -0 0</wrench>
        </link>
      </model>
      <model name='asphalt_plane'>
        <pose>0 0 0 0 -0 0</pose>
        <scale>1 1 1</scale>
        <link name='link'>
          <pose>0 0 0 0 -0 0</pose>
          <velocity>0 0 0 0 -0 0</velocity>
          <acceleration>0 0 0 0 -0 0</acceleration>
          <wrench>0 0 0 0 -0 0</wrench>
        </link>
      </model>
      <model name='grass_plane'>
        <pose>14 0 0.15 0 -0 0</pose>
        <scale>1 1 1</scale>
        <link name='link'>
          <pose>14 0 0.15 0 -0 0</pose>
          <velocity>0 0 0 0 -0 0</velocity>
          <acceleration>0 0 0 0 -0 0</acceleration>
          <wrench>0 0 0 0 -0 0</wrench>
        </link>
      </model>
      <model name='grass_plane_0'>
        <pose>-14 0 0.15 0 -0 0</pose>
        <scale>1 1 1</scale>
        <link name='link'>
          <pose>-14 0 0.15 0 -0 0</pose>
          <velocity>0 0 0 0 -0 0</velocity>
          <acceleration>0 0 0 0 -0 0</acceleration>
          <wrench>0 0 0 0 -0 0</wrench>
        </link>
      </model>
      <model name='jersey_barrier'>
        <pose>-1.80444 49.428 0 0 -0 0</pose>
        <scale>1 1 1</scale>
        <link name='link'>
          <pose>-1.80444 49.428 0 0 -0 0</pose>
          <velocity>0 0 0 0 -0 0</velocity>
          <acceleration>0 0 0 0 -0 0</acceleration>
          <wrench>0 0 0 0 -0 0</wrench>
        </link>
      </model>
      <model name='jersey_barrier_0'>
        <pose>1.78613 49.4153 0 0 -0 0</pose>
        <scale>1 1 1</scale>
        <link name='link'>
          <pose>1.78613 49.4153 0 0 -0 0</pose>
          <velocity>0 0 0 0 -0 0</velocity>
          <acceleration>0 0 0 0 -0 0</acceleration>
          <wrench>0 0 0 0 -0 0</wrench>
        </link>
      </model>
      <model name='jersey_barrier_0_clone'>
        <pose>-1.76009 -49.5671 0 0 -0 0</pose>
        <scale>1 1 1</scale>
        <link name='link'>
          <pose>-1.76009 -49.5671 0 0 -0 0</pose>
          <velocity>0 0 0 0 -0 0</velocity>
          <acceleration>0 0 0 0 -0 0</acceleration>
          <wrench>0 0 0 0 -0 0</wrench>
        </link>
      </model>
      <model name='jersey_barrier_0_clone_0'>
        <pose>1.80772 -49.5538 0 0 -0 0</pose>
        <scale>1 1 1</scale>
        <link name='link'>
          <pose>1.80772 -49.5538 0 0 -0 0</pose>
          <velocity>0 0 0 0 -0 0</velocity>
          <acceleration>0 0 0 0 -0 0</acceleration>
          <wrench>0 0 0 0 -0 0</wrench>
        </link>
      </model>
      <model name='prius'>
        <pose>1.52626 -47.9229 0.056906 0 0.000235 1.61787</pose>
        <scale>1 1 1</scale>
        <link name='chassis'>
          <pose>1.45806 -46.4745 0.057487 4.4e-05 -0 -3.09533</pose>
          <velocity>-0.000405 -0.004182 -0.015163 0.005326 0.000253 0.000425</velocity>
          <acceleration>0.015328 0.638614 0.020013 0.220845 0.012762 -0.012738</acceleration>
          <wrench>20.8311 867.876 27.197 0 -0 0</wrench>
        </link>
        <link name='dummy'>
          <pose>1.52626 -47.9229 0.056906 0 0.000235 1.61787</pose>
          <velocity>-0.000616 -0.005196 -0.001874 0.011543 0.000551 0.054913</velocity>
          <acceleration>1.26724 -1.44733 0.000307 0.308591 0.019479 -0.618437</acceleration>
          <wrench>1.26724 -1.44733 0.000307 0 -0 0</wrench>
        </link>
        <link name='fl_axle'>
          <pose>0.626673 -45.1015 0.357607 0.002857 2.8e-05 -3.09372</pose>
          <velocity>-0.000613 -0.000552 -0.02899 0.196979 -0.015523 2.91165</velocity>
          <acceleration>0.653335 11.1178 -0.067858 -0.697616 -0.075316 -2.06603</acceleration>
          <wrench>0.653335 11.1178 -0.067858 0 -0 0</wrench>
        </link>
        <link name='fr_axle'>
          <pose>2.15903 -45.0306 0.357607 0.002919 -9.8e-05 -3.09698</pose>
          <velocity>-0.000969 0.000277 -0.029006 0.204432 -0.011556 -2.9782</velocity>
          <acceleration>-0.002664 11.4152 -0.075097 -2.1961 1.36946 2.3267</acceleration>
          <wrench>-0.002664 11.4152 -0.075097 0 -0 0</wrench>
        </link>
        <link name='front_left_wheel'>
          <pose>0.626673 -45.1015 0.357567 2.16307 2e-05 -3.09372</pose>
          <velocity>-0.000596 -0.000457 -0.024234 0.318258 -0.001901 2.91162</velocity>
          <acceleration>0.679075 11.5214 0.018414 0.250299 0.494887 1.00202</acceleration>
          <wrench>7.46982 126.735 0.202557 0 -0 0</wrench>
        </link>
        <link name='front_right_wheel'>
          <pose>2.15903 -45.0306 0.357566 -1.01049 -7e-05 -3.09698</pose>
          <velocity>-0.000961 0.00037 -0.024226 0.327724 -0.003124 -2.97822</velocity>
          <acceleration>0.006372 11.8204 0.012651 1.77295 1.53355 -0.804148</acceleration>
          <wrench>0.070088 130.024 0.139162 0 -0 0</wrench>
        </link>
        <link name='rear_left_wheel'>
          <pose>0.73297 -47.9596 0.357557 1.69011 3e-06 -3.09533</pose>
          <velocity>0.000342 -0.007042 -0.023591 0.022501 0.001072 0.000426</velocity>
          <acceleration>0.001558 0.394186 -0.230834 -1.2506 0.051051 -0.011979</acceleration>
          <wrench>0.017134 4.33605 -2.53918 0 -0 0</wrench>
        </link>
        <link name='rear_right_wheel'>
          <pose>2.31727 -47.8862 0.357557 -1.42374 2e-06 -3.09533</pose>
          <velocity>0.000312 -0.006362 -0.02356 0.020341 0.000977 0.000424</velocity>
          <acceleration>0.002479 0.382755 -0.230688 -1.2142 0.052665 -0.012341</acceleration>
          <wrench>0.027265 4.21031 -2.53757 0 -0 0</wrench>
        </link>
        <link name='steering_wheel'>
          <pose>1.07167 -45.8638 1.0457 -1.30206 0 -3.09533</pose>
          <velocity>-0.000414 -0.009648 -0.011728 0.005395 0.000202 0.00044</velocity>
          <acceleration>0.024703 0.519764 0.153106 0.220083 -0.085214 0.014664</acceleration>
          <wrench>0.024703 0.519764 0.153106 0 -0 0</wrench>
        </link>
      </model>
      <model name='road_border'>
        <pose>-3.94075 0.142475 0.15 0 -0 2e-05</pose>
        <scale>1 1 1</scale>
        <link name='link_0'>
          <pose>-3.94075 0.142475 0.15 0 -0 2e-05</pose>
          <velocity>0 0 0 0 -0 0</velocity>
          <acceleration>0 0 0 0 -0 0</acceleration>
          <wrench>0 0 0 0 -0 0</wrench>
        </link>
      </model>
      <model name='road_border_clone'>
        <pose>3.94 0 0.15 0 -0 0</pose>
        <scale>1 1 1</scale>
        <link name='link_0'>
          <pose>3.94 0 0.15 0 -0 0</pose>
          <velocity>0 0 0 0 -0 0</velocity>
          <acceleration>0 0 0 0 -0 0</acceleration>
          <wrench>0 0 0 0 -0 0</wrench>
        </link>
      </model>
      <light name='sun'>
        <pose>0 0 50 0 -0 0</pose>
      </light>
    </state>
    <model name='Construction Cone_0_clone'>
      <link name='link'>
        <collision name='collision'>
          <geometry>
            <mesh>
              <scale>10 10 10</scale>
              <uri>model://construction_cone/meshes/construction_cone.dae</uri>
            </mesh>
          </geometry>
          <max_contacts>10</max_contacts>
          <surface>
            <contact>
              <ode/>
            </contact>
            <bounce/>
            <friction>
              <torsional>
                <ode/>
              </torsional>
              <ode/>
            </friction>
          </surface>
        </collision>
        <visual name='visual'>
          <geometry>
            <mesh>
              <scale>10 10 10</scale>
              <uri>model://construction_cone/meshes/construction_cone.dae</uri>
            </mesh>
          </geometry>
        </visual>
        <self_collide>0</self_collide>
        <inertial>
          <pose>0 0 0 0 -0 0</pose>
          <inertia>
            <ixx>1</ixx>
            <ixy>0</ixy>
            <ixz>0</ixz>
            <iyy>1</iyy>
            <iyz>0</iyz>
            <izz>1</izz>
          </inertia>
          <mass>1</mass>
        </inertial>
        <enable_wind>0</enable_wind>
        <kinematic>0</kinematic>
      </link>
      <pose>2.14718 13.7047 0.207015 3e-06 -2e-06 -2.02232</pose>
    </model>
    <gui fullscreen='0'>
      <camera name='user_camera'>
        <pose>13.9058 -99.3769 59.2885 -0 0.693795 1.44096</pose>
        <view_controller>orbit</view_controller>
        <projection_type>perspective</projection_type>
      </camera>
    </gui>
    <model name='road_border'>
      <link name='link_0'>
        <inertial>
          <mass>1</mass>
          <inertia>
            <ixx>0.166667</ixx>
            <ixy>0</ixy>
            <ixz>0</ixz>
            <iyy>0.166667</iyy>
            <iyz>0</iyz>
            <izz>0.166667</izz>
          </inertia>
          <pose>0 0 0 0 -0 0</pose>
        </inertial>
        <pose>2e-06 0 -0 0 -0 0</pose>
        <gravity>1</gravity>
        <self_collide>0</self_collide>
        <kinematic>0</kinematic>
        <enable_wind>0</enable_wind>
        <visual name='visual'>
          <pose>0 0 0 0 -0 0</pose>
          <geometry>
            <box>
              <size>0.2 100 0.2</size>
            </box>
          </geometry>
          <material>
            <lighting>1</lighting>
            <script>
              <uri>file://media/materials/scripts/gazebo.material</uri>
              <name>Gazebo/Yellow</name>
            </script>
            <shader type='pixel'>
              <normal_map>__default__</normal_map>
            </shader>
            <ambient>0.255 0.239 0 1</ambient>
            <diffuse>0.7 0.7 0.7 1</diffuse>
            <specular>0.01 0.01 0.01 1</specular>
            <emissive>0 0 0 1</emissive>
          </material>
          <transparency>0</transparency>
          <cast_shadows>1</cast_shadows>
        </visual>
        <collision name='collision'>
          <laser_retro>0</laser_retro>
          <max_contacts>10</max_contacts>
          <pose>0 0 0 0 -0 0</pose>
          <geometry>
            <box>
              <size>0.2 100 0.2</size>
            </box>
          </geometry>
          <surface>
            <friction>
              <ode>
                <mu>1</mu>
                <mu2>1</mu2>
                <fdir1>0 0 0</fdir1>
                <slip1>0</slip1>
                <slip2>0</slip2>
              </ode>
              <torsional>
                <coefficient>1</coefficient>
                <patch_radius>0</patch_radius>
                <surface_radius>0</surface_radius>
                <use_patch_radius>1</use_patch_radius>
                <ode>
                  <slip>0</slip>
                </ode>
              </torsional>
            </friction>
            <bounce>
              <restitution_coefficient>0</restitution_coefficient>
              <threshold>1e+06</threshold>
            </bounce>
            <contact>
              <collide_without_contact>0</collide_without_contact>
              <collide_without_contact_bitmask>1</collide_without_contact_bitmask>
              <collide_bitmask>1</collide_bitmask>
              <ode>
                <soft_cfm>0</soft_cfm>
                <soft_erp>0.2</soft_erp>
                <kp>1e+13</kp>
                <kd>1</kd>
                <max_vel>0.01</max_vel>
                <min_depth>0</min_depth>
              </ode>
              <bullet>
                <split_impulse>1</split_impulse>
                <split_impulse_penetration_threshold>-0.01</split_impulse_penetration_threshold>
                <soft_cfm>0</soft_cfm>
                <soft_erp>0.2</soft_erp>
                <kp>1e+13</kp>
                <kd>1</kd>
              </bullet>
            </contact>
          </surface>
        </collision>
      </link>
      <static>1</static>
      <allow_auto_disable>1</allow_auto_disable>
      <pose>-3.94655 0.144288 0.624007 -0.002899 -0.009266 2.2e-05</pose>
    </model>
    <model name='road_border_clone'>
      <link name='link_0'>
        <inertial>
          <mass>1</mass>
          <inertia>
            <ixx>0.166667</ixx>
            <ixy>0</ixy>
            <ixz>0</ixz>
            <iyy>0.166667</iyy>
            <iyz>0</iyz>
            <izz>0.166667</izz>
          </inertia>
          <pose>0 0 0 0 -0 0</pose>
        </inertial>
        <pose>2e-06 0 -0 0 -0 0</pose>
        <gravity>1</gravity>
        <self_collide>0</self_collide>
        <kinematic>0</kinematic>
        <enable_wind>0</enable_wind>
        <visual name='visual'>
          <pose>0 0 0 0 -0 0</pose>
          <geometry>
            <box>
              <size>0.2 100 0.2</size>
            </box>
          </geometry>
          <material>
            <lighting>1</lighting>
            <script>
              <uri>file://media/materials/scripts/gazebo.material</uri>
              <name>Gazebo/Yellow</name>
            </script>
            <shader type='pixel'>
              <normal_map>__default__</normal_map>
            </shader>
            <ambient>0.255 0.239 0 1</ambient>
            <diffuse>0.7 0.7 0.7 1</diffuse>
            <specular>0.01 0.01 0.01 1</specular>
            <emissive>0 0 0 1</emissive>
          </material>
          <transparency>0</transparency>
          <cast_shadows>1</cast_shadows>
        </visual>
        <collision name='collision'>
          <laser_retro>0</laser_retro>
          <max_contacts>10</max_contacts>
          <pose>0 0 0 0 -0 0</pose>
          <geometry>
            <box>
              <size>0.2 100 0.2</size>
            </box>
          </geometry>
          <surface>
            <friction>
              <ode>
                <mu>1</mu>
                <mu2>1</mu2>
                <fdir1>0 0 0</fdir1>
                <slip1>0</slip1>
                <slip2>0</slip2>
              </ode>
              <torsional>
                <coefficient>1</coefficient>
                <patch_radius>0</patch_radius>
                <surface_radius>0</surface_radius>
                <use_patch_radius>1</use_patch_radius>
                <ode>
                  <slip>0</slip>
                </ode>
              </torsional>
            </friction>
            <bounce>
              <restitution_coefficient>0</restitution_coefficient>
              <threshold>1e+06</threshold>
            </bounce>
            <contact>
              <collide_without_contact>0</collide_without_contact>
              <collide_without_contact_bitmask>1</collide_without_contact_bitmask>
              <collide_bitmask>1</collide_bitmask>
              <ode>
                <soft_cfm>0</soft_cfm>
                <soft_erp>0.2</soft_erp>
                <kp>1e+13</kp>
                <kd>1</kd>
                <max_vel>0.01</max_vel>
                <min_depth>0</min_depth>
              </ode>
              <bullet>
                <split_impulse>1</split_impulse>
                <split_impulse_penetration_threshold>-0.01</split_impulse_penetration_threshold>
                <soft_cfm>0</soft_cfm>
                <soft_erp>0.2</soft_erp>
                <kp>1e+13</kp>
                <kd>1</kd>
              </bullet>
            </contact>
          </surface>
        </collision>
      </link>
      <static>1</static>
      <allow_auto_disable>1</allow_auto_disable>
      <pose>4 -46.4336 0.15 0 -0 0</pose>
    </model>
    <model name='asphalt_plane'>
      <static>1</static>
      <link name='link'>
        <collision name='collision'>
          <geometry>
            <box>
              <size>20 100 0.1</size>
            </box>
          </geometry>
          <max_contacts>10</max_contacts>
          <surface>
            <contact>
              <ode/>
            </contact>
            <bounce/>
            <friction>
              <torsional>
                <ode/>
              </torsional>
              <ode/>
            </friction>
          </surface>
        </collision>
        <visual name='visual'>
          <cast_shadows>0</cast_shadows>
          <geometry>
            <box>
              <size>20 100 0.1</size>
            </box>
          </geometry>
          <material>
            <script>
              <uri>model://asphalt_plane/materials/scripts</uri>
              <uri>model://asphalt_plane/materials/textures</uri>
              <name>vrc/asphalt</name>
            </script>
          </material>
        </visual>
        <self_collide>0</self_collide>
        <enable_wind>0</enable_wind>
        <kinematic>0</kinematic>
      </link>
      <pose>-0.752886 -1.1254 0 0 -0 0</pose>
    </model>
    <model name='grass_plane'>
      <static>1</static>
      <link name='link'>
        <visual name='visual'>
          <geometry>
            <box>
              <size>20 100 0.2</size>
            </box>
          </geometry>
          <material>
            <script>
              <uri>file://media/materials/scripts/gazebo.material</uri>
              <name>Gazebo/Grass</name>
            </script>
          </material>
        </visual>
        <collision name='collision'>
          <geometry>
            <box>
              <size>20 100 0.2</size>
            </box>
          </geometry>
          <max_contacts>10</max_contacts>
          <surface>
            <contact>
              <ode/>
            </contact>
            <bounce/>
            <friction>
              <torsional>
                <ode/>
              </torsional>
              <ode/>
            </friction>
          </surface>
        </collision>
        <self_collide>0</self_collide>
        <enable_wind>0</enable_wind>
        <kinematic>0</kinematic>
      </link>
      <pose>13.1384 -19.6682 0 0 -0 0</pose>
    </model>
    <model name='grass_plane_0'>
      <static>1</static>
      <link name='link'>
        <visual name='visual'>
          <geometry>
            <box>
              <size>20 100 0.2</size>
            </box>
          </geometry>
          <material>
            <script>
              <uri>file://media/materials/scripts/gazebo.material</uri>
              <name>Gazebo/Grass</name>
            </script>
          </material>
        </visual>
        <collision name='collision'>
          <geometry>
            <box>
              <size>20 100 0.2</size>
            </box>
          </geometry>
          <max_contacts>10</max_contacts>
          <surface>
            <contact>
              <ode/>
            </contact>
            <bounce/>
            <friction>
              <torsional>
                <ode/>
              </torsional>
              <ode/>
            </friction>
          </surface>
        </collision>
        <self_collide>0</self_collide>
        <enable_wind>0</enable_wind>
        <kinematic>0</kinematic>
      </link>
      <pose>-9.39661 -44.6357 0 0 -0 0</pose>
    </model>
    <model name='jersey_barrier'>
      <static>1</static>
      <link name='link'>
        <visual name='visual'>
          <geometry>
            <mesh>
              <uri>model://jersey_barrier/meshes/jersey_barrier.dae</uri>
            </mesh>
          </geometry>
        </visual>
        <collision name='upright'>
          <pose>0 0 0.5715 0 -0 0</pose>
          <geometry>
            <box>
              <size>4.06542 0.3063 1.143</size>
            </box>
          </geometry>
          <max_contacts>10</max_contacts>
          <surface>
            <contact>
              <ode/>
            </contact>
            <bounce/>
            <friction>
              <torsional>
                <ode/>
              </torsional>
              <ode/>
            </friction>
          </surface>
        </collision>
        <collision name='base'>
          <pose>0 0 0.032258 0 -0 0</pose>
          <geometry>
            <box>
              <size>4.06542 0.8107 0.064516</size>
            </box>
          </geometry>
          <max_contacts>10</max_contacts>
          <surface>
            <contact>
              <ode/>
            </contact>
            <bounce/>
            <friction>
              <torsional>
                <ode/>
              </torsional>
              <ode/>
            </friction>
          </surface>
        </collision>
        <collision name='base2'>
          <pose>0 0 0.1 0 -0 0</pose>
          <geometry>
            <box>
              <size>4.06542 0.65 0.1</size>
            </box>
          </geometry>
          <max_contacts>10</max_contacts>
          <surface>
            <contact>
              <ode/>
            </contact>
            <bounce/>
            <friction>
              <torsional>
                <ode/>
              </torsional>
              <ode/>
            </friction>
          </surface>
        </collision>
        <collision name='base3'>
          <pose>0 0 0.2 0 -0 0</pose>
          <geometry>
            <box>
              <size>4.06542 0.5 0.1</size>
            </box>
          </geometry>
          <max_contacts>10</max_contacts>
          <surface>
            <contact>
              <ode/>
            </contact>
            <bounce/>
            <friction>
              <torsional>
                <ode/>
              </torsional>
              <ode/>
            </friction>
          </surface>
        </collision>
        <collision name='left-angle'>
          <pose>0 -0.224 0.2401 0.9 -0 0</pose>
          <geometry>
            <box>
              <size>4.06542 0.5 0.064516</size>
            </box>
          </geometry>
          <max_contacts>10</max_contacts>
          <surface>
            <contact>
              <ode/>
            </contact>
            <bounce/>
            <friction>
              <torsional>
                <ode/>
              </torsional>
              <ode/>
            </friction>
          </surface>
        </collision>
        <collision name='right-angle'>
          <pose>0 0.224 0.2401 -0.9 0 0</pose>
          <geometry>
            <box>
              <size>4.06542 0.5 0.064516</size>
            </box>
          </geometry>
          <max_contacts>10</max_contacts>
          <surface>
            <contact>
              <ode/>
            </contact>
            <bounce/>
            <friction>
              <torsional>
                <ode/>
              </torsional>
              <ode/>
            </friction>
          </surface>
        </collision>
        <self_collide>0</self_collide>
        <enable_wind>0</enable_wind>
        <kinematic>0</kinematic>
      </link>
      <pose>-1.87694 49.4493 0 0 -0 0</pose>
    </model>
    <model name='jersey_barrier_0'>
      <static>1</static>
      <link name='link'>
        <visual name='visual'>
          <geometry>
            <mesh>
              <uri>model://jersey_barrier/meshes/jersey_barrier.dae</uri>
            </mesh>
          </geometry>
        </visual>
        <collision name='upright'>
          <pose>0 0 0.5715 0 -0 0</pose>
          <geometry>
            <box>
              <size>4.06542 0.3063 1.143</size>
            </box>
          </geometry>
          <max_contacts>10</max_contacts>
          <surface>
            <contact>
              <ode/>
            </contact>
            <bounce/>
            <friction>
              <torsional>
                <ode/>
              </torsional>
              <ode/>
            </friction>
          </surface>
        </collision>
        <collision name='base'>
          <pose>0 0 0.032258 0 -0 0</pose>
          <geometry>
            <box>
              <size>4.06542 0.8107 0.064516</size>
            </box>
          </geometry>
          <max_contacts>10</max_contacts>
          <surface>
            <contact>
              <ode/>
            </contact>
            <bounce/>
            <friction>
              <torsional>
                <ode/>
              </torsional>
              <ode/>
            </friction>
          </surface>
        </collision>
        <collision name='base2'>
          <pose>0 0 0.1 0 -0 0</pose>
          <geometry>
            <box>
              <size>4.06542 0.65 0.1</size>
            </box>
          </geometry>
          <max_contacts>10</max_contacts>
          <surface>
            <contact>
              <ode/>
            </contact>
            <bounce/>
            <friction>
              <torsional>
                <ode/>
              </torsional>
              <ode/>
            </friction>
          </surface>
        </collision>
        <collision name='base3'>
          <pose>0 0 0.2 0 -0 0</pose>
          <geometry>
            <box>
              <size>4.06542 0.5 0.1</size>
            </box>
          </geometry>
          <max_contacts>10</max_contacts>
          <surface>
            <contact>
              <ode/>
            </contact>
            <bounce/>
            <friction>
              <torsional>
                <ode/>
              </torsional>
              <ode/>
            </friction>
          </surface>
        </collision>
        <collision name='left-angle'>
          <pose>0 -0.224 0.2401 0.9 -0 0</pose>
          <geometry>
            <box>
              <size>4.06542 0.5 0.064516</size>
            </box>
          </geometry>
          <max_contacts>10</max_contacts>
          <surface>
            <contact>
              <ode/>
            </contact>
            <bounce/>
            <friction>
              <torsional>
                <ode/>
              </torsional>
              <ode/>
            </friction>
          </surface>
        </collision>
        <collision name='right-angle'>
          <pose>0 0.224 0.2401 -0.9 0 0</pose>
          <geometry>
            <box>
              <size>4.06542 0.5 0.064516</size>
            </box>
          </geometry>
          <max_contacts>10</max_contacts>
          <surface>
            <contact>
              <ode/>
            </contact>
            <bounce/>
            <friction>
              <torsional>
                <ode/>
              </torsional>
              <ode/>
            </friction>
          </surface>
        </collision>
        <self_collide>0</self_collide>
        <enable_wind>0</enable_wind>
        <kinematic>0</kinematic>
      </link>
      <pose>2.20165 49.3928 0 0 -0 0</pose>
    </model>
    <model name='jersey_barrier_0_clone'>
      <static>1</static>
      <link name='link'>
        <visual name='visual'>
          <geometry>
            <mesh>
              <uri>model://jersey_barrier/meshes/jersey_barrier.dae</uri>
            </mesh>
          </geometry>
        </visual>
        <collision name='upright'>
          <pose>0 0 0.5715 0 -0 0</pose>
          <geometry>
            <box>
              <size>4.06542 0.3063 1.143</size>
            </box>
          </geometry>
          <max_contacts>10</max_contacts>
          <surface>
            <contact>
              <ode/>
            </contact>
            <bounce/>
            <friction>
              <torsional>
                <ode/>
              </torsional>
              <ode/>
            </friction>
          </surface>
        </collision>
        <collision name='base'>
          <pose>0 0 0.032258 0 -0 0</pose>
          <geometry>
            <box>
              <size>4.06542 0.8107 0.064516</size>
            </box>
          </geometry>
          <max_contacts>10</max_contacts>
          <surface>
            <contact>
              <ode/>
            </contact>
            <bounce/>
            <friction>
              <torsional>
                <ode/>
              </torsional>
              <ode/>
            </friction>
          </surface>
        </collision>
        <collision name='base2'>
          <pose>0 0 0.1 0 -0 0</pose>
          <geometry>
            <box>
              <size>4.06542 0.65 0.1</size>
            </box>
          </geometry>
          <max_contacts>10</max_contacts>
          <surface>
            <contact>
              <ode/>
            </contact>
            <bounce/>
            <friction>
              <torsional>
                <ode/>
              </torsional>
              <ode/>
            </friction>
          </surface>
        </collision>
        <collision name='base3'>
          <pose>0 0 0.2 0 -0 0</pose>
          <geometry>
            <box>
              <size>4.06542 0.5 0.1</size>
            </box>
          </geometry>
          <max_contacts>10</max_contacts>
          <surface>
            <contact>
              <ode/>
            </contact>
            <bounce/>
            <friction>
              <torsional>
                <ode/>
              </torsional>
              <ode/>
            </friction>
          </surface>
        </collision>
        <collision name='left-angle'>
          <pose>0 -0.224 0.2401 0.9 -0 0</pose>
          <geometry>
            <box>
              <size>4.06542 0.5 0.064516</size>
            </box>
          </geometry>
          <max_contacts>10</max_contacts>
          <surface>
            <contact>
              <ode/>
            </contact>
            <bounce/>
            <friction>
              <torsional>
                <ode/>
              </torsional>
              <ode/>
            </friction>
          </surface>
        </collision>
        <collision name='right-angle'>
          <pose>0 0.224 0.2401 -0.9 0 0</pose>
          <geometry>
            <box>
              <size>4.06542 0.5 0.064516</size>
            </box>
          </geometry>
          <max_contacts>10</max_contacts>
          <surface>
            <contact>
              <ode/>
            </contact>
            <bounce/>
            <friction>
              <torsional>
                <ode/>
              </torsional>
              <ode/>
            </friction>
          </surface>
        </collision>
        <self_collide>0</self_collide>
        <enable_wind>0</enable_wind>
        <kinematic>0</kinematic>
      </link>
      <pose>-1.74655 -49.479 0 0 -0 0</pose>
    </model>
    <model name='jersey_barrier_0_clone_0'>
      <static>1</static>
      <link name='link'>
        <visual name='visual'>
          <geometry>
            <mesh>
              <uri>model://jersey_barrier/meshes/jersey_barrier.dae</uri>
            </mesh>
          </geometry>
        </visual>
        <collision name='upright'>
          <pose>0 0 0.5715 0 -0 0</pose>
          <geometry>
            <box>
              <size>4.06542 0.3063 1.143</size>
            </box>
          </geometry>
          <max_contacts>10</max_contacts>
          <surface>
            <contact>
              <ode/>
            </contact>
            <bounce/>
            <friction>
              <torsional>
                <ode/>
              </torsional>
              <ode/>
            </friction>
          </surface>
        </collision>
        <collision name='base'>
          <pose>0 0 0.032258 0 -0 0</pose>
          <geometry>
            <box>
              <size>4.06542 0.8107 0.064516</size>
            </box>
          </geometry>
          <max_contacts>10</max_contacts>
          <surface>
            <contact>
              <ode/>
            </contact>
            <bounce/>
            <friction>
              <torsional>
                <ode/>
              </torsional>
              <ode/>
            </friction>
          </surface>
        </collision>
        <collision name='base2'>
          <pose>0 0 0.1 0 -0 0</pose>
          <geometry>
            <box>
              <size>4.06542 0.65 0.1</size>
            </box>
          </geometry>
          <max_contacts>10</max_contacts>
          <surface>
            <contact>
              <ode/>
            </contact>
            <bounce/>
            <friction>
              <torsional>
                <ode/>
              </torsional>
              <ode/>
            </friction>
          </surface>
        </collision>
        <collision name='base3'>
          <pose>0 0 0.2 0 -0 0</pose>
          <geometry>
            <box>
              <size>4.06542 0.5 0.1</size>
            </box>
          </geometry>
          <max_contacts>10</max_contacts>
          <surface>
            <contact>
              <ode/>
            </contact>
            <bounce/>
            <friction>
              <torsional>
                <ode/>
              </torsional>
              <ode/>
            </friction>
          </surface>
        </collision>
        <collision name='left-angle'>
          <pose>0 -0.224 0.2401 0.9 -0 0</pose>
          <geometry>
            <box>
              <size>4.06542 0.5 0.064516</size>
            </box>
          </geometry>
          <max_contacts>10</max_contacts>
          <surface>
            <contact>
              <ode/>
            </contact>
            <bounce/>
            <friction>
              <torsional>
                <ode/>
              </torsional>
              <ode/>
            </friction>
          </surface>
        </collision>
        <collision name='right-angle'>
          <pose>0 0.224 0.2401 -0.9 0 0</pose>
          <geometry>
            <box>
              <size>4.06542 0.5 0.064516</size>
            </box>
          </geometry>
          <max_contacts>10</max_contacts>
          <surface>
            <contact>
              <ode/>
            </contact>
            <bounce/>
            <friction>
              <torsional>
                <ode/>
              </torsional>
              <ode/>
            </friction>
          </surface>
        </collision>
        <self_collide>0</self_collide>
        <enable_wind>0</enable_wind>
        <kinematic>0</kinematic>
      </link>
      <pose>1.8216 -49.4803 0 0 -0 0</pose>
    </model>
    <model name='prius'>
      <link name='dummy'>
        <inertial>
          <pose>0 0 0 0 -0 0</pose>
          <mass>1</mass>
          <inertia>
            <ixx>0.001</ixx>
            <ixy>0</ixy>
            <ixz>0</ixz>
            <iyy>0.001</iyy>
            <iyz>0</iyz>
            <izz>0.001</izz>
          </inertia>
        </inertial>
        <self_collide>0</self_collide>
        <enable_wind>0</enable_wind>
        <kinematic>0</kinematic>
      </link>
      <joint name='base_link_connection' type='revolute'>
        <pose relative_to='dummy'>1.45 0 0 0 -0 1.57</pose>
        <parent>dummy</parent>
        <child>chassis</child>
        <axis>
          <limit>
            <lower>0</lower>
            <upper>0</upper>
          </limit>
          <dynamics>
            <damping>0</damping>
            <friction>0</friction>
            <spring_reference>0</spring_reference>
            <spring_stiffness>0</spring_stiffness>
          </dynamics>
          <xyz>0 0 1</xyz>
        </axis>
        <physics>
          <ode>
            <limit>
              <cfm>0</cfm>
              <erp>0.2</erp>
            </limit>
          </ode>
        </physics>
      </joint>
      <link name='chassis'>
        <pose relative_to='base_link_connection'>0 0 0 0 -0 0</pose>
        <inertial>
          <pose>0 -0.00103 0.481884 0 -0 1.5708</pose>
          <mass>1359</mass>
          <inertia>
            <ixx>2583.64</ixx>
            <ixy>6.53301e-06</ixy>
            <ixz>0.585363</ixz>
            <iyy>595.596</iyy>
            <iyz>-2.15016e-06</iyz>
            <izz>2683.73</izz>
          </inertia>
        </inertial>
        <collision name='chassis_collision'>
          <pose>0 0.05 0.625 0 -0 0</pose>
          <geometry>
            <box>
              <size>1.7526 2.1 0.95</size>
            </box>
          </geometry>
          <max_contacts>10</max_contacts>
          <surface>
            <contact>
              <ode/>
            </contact>
            <bounce/>
            <friction>
              <torsional>
                <ode/>
              </torsional>
              <ode/>
            </friction>
          </surface>
        </collision>
        <collision name='chassis_fixed_joint_lump__front_bumper_collision_1'>
          <pose>0 -2 0.458488 0 -0 0</pose>
          <geometry>
            <box>
              <size>1.33728 0.48 0.566691</size>
            </box>
          </geometry>
          <max_contacts>10</max_contacts>
          <surface>
            <contact>
              <ode/>
            </contact>
            <bounce/>
            <friction>
              <torsional>
                <ode/>
              </torsional>
              <ode/>
            </friction>
          </surface>
        </collision>
        <collision name='chassis_fixed_joint_lump__hood_collision_2'>
          <pose>0 -1.90084 0.676305 0.341247 -0 0</pose>
          <geometry>
            <box>
              <size>1.59797 0.493107 0.265468</size>
            </box>
          </geometry>
          <max_contacts>10</max_contacts>
          <surface>
            <contact>
              <ode/>
            </contact>
            <bounce/>
            <friction>
              <torsional>
                <ode/>
              </torsional>
              <ode/>
            </friction>
          </surface>
        </collision>
        <collision name='chassis_fixed_joint_lump__windshield_collision_3'>
          <pose>0 -0.875105 1.03227 0.335476 -0 0</pose>
          <geometry>
            <box>
              <size>1.16838 1.65425 0.272347</size>
            </box>
          </geometry>
          <max_contacts>10</max_contacts>
          <surface>
            <contact>
              <ode/>
            </contact>
            <bounce/>
            <friction>
              <torsional>
                <ode/>
              </torsional>
              <ode/>
            </friction>
          </surface>
        </collision>
        <collision name='chassis_fixed_joint_lump__top_front_collision_4'>
          <pose>0 0.161236 1.38604 0.13503 -0 0</pose>
          <geometry>
            <box>
              <size>1.27915 0.625988 0.171868</size>
            </box>
          </geometry>
          <max_contacts>10</max_contacts>
          <surface>
            <contact>
              <ode/>
            </contact>
            <bounce/>
            <friction>
              <torsional>
                <ode/>
              </torsional>
              <ode/>
            </friction>
          </surface>
        </collision>
        <collision name='chassis_fixed_joint_lump__top_rear_collision_5'>
          <pose>0 0.817696 1.36007 -0.068997 0 0</pose>
          <geometry>
            <box>
              <size>1.28513 0.771189 0.226557</size>
            </box>
          </geometry>
          <max_contacts>10</max_contacts>
          <surface>
            <contact>
              <ode/>
            </contact>
            <bounce/>
            <friction>
              <torsional>
                <ode/>
              </torsional>
              <ode/>
            </friction>
          </surface>
        </collision>
        <collision name='chassis_fixed_joint_lump__rear_window_collision_6'>
          <pose>0 1.64053 1.17513 -0.262017 0 0</pose>
          <geometry>
            <box>
              <size>1.26785 1.11634 0.244286</size>
            </box>
          </geometry>
          <max_contacts>10</max_contacts>
          <surface>
            <contact>
              <ode/>
            </contact>
            <bounce/>
            <friction>
              <torsional>
                <ode/>
              </torsional>
              <ode/>
            </friction>
          </surface>
        </collision>
        <collision name='chassis_fixed_joint_lump__trunk_collision_7'>
          <pose>0 1.63706 0.88818 0 -0 0</pose>
          <geometry>
            <box>
              <size>1.78806 1.13899 0.482746</size>
            </box>
          </geometry>
          <max_contacts>10</max_contacts>
          <surface>
            <contact>
              <ode/>
            </contact>
            <bounce/>
            <friction>
              <torsional>
                <ode/>
              </torsional>
              <ode/>
            </friction>
          </surface>
        </collision>
        <collision name='chassis_fixed_joint_lump__back_bumper_collision_8'>
          <pose>0 2.05445 0.57787 0 -0 0</pose>
          <geometry>
            <box>
              <size>1.78165 0.512093 0.581427</size>
            </box>
          </geometry>
          <max_contacts>10</max_contacts>
          <surface>
            <contact>
              <ode/>
            </contact>
            <bounce/>
            <friction>
              <torsional>
                <ode/>
              </torsional>
              <ode/>
            </friction>
          </surface>
        </collision>
        <visual name='chassis_visual'>
          <pose>0 0 0 0 -0 0</pose>
          <geometry>
            <mesh>
              <scale>0.01 0.01 0.01</scale>
              <uri>model://prius_description/meshes/hybrid_body.obj</uri>
            </mesh>
          </geometry>
        </visual>
        <sensor name='center_laser_sensor' type='gpu_ray'>
          <visualize>0</visualize>
          <update_rate>20</update_rate>
          <always_on>1</always_on>
          <ray>
            <scan>
              <vertical>
                <samples>128</samples>
                <resolution>1</resolution>
                <min_angle>-0.19635</min_angle>
                <max_angle>0.19635</max_angle>
              </vertical>
              <horizontal>
                <samples>1024</samples>
                <resolution>1</resolution>
                <min_angle>-3.14</min_angle>
                <max_angle>3.14</max_angle>
              </horizontal>
            </scan>
            <range>
              <min>0.8</min>
              <max>200</max>
              <resolution>0.03</resolution>
            </range>
            <noise>
              <type>gaussian</type>
              <mean>0</mean>
              <stddev>0.01</stddev>
            </noise>
          </ray>
          <plugin name='center_laser_sensor' filename='libgazebo_ros_ray_sensor.so'>
            <ros>
              <namespace>prius</namespace>
              <argument>~/out:=center_laser/scan</argument>
            </ros>
            <frame_name>center_laser_link</frame_name>
            <output_type>sensor_msgs/PointCloud2</output_type>
          </plugin>
          <pose>0 0.4 1.8 0 0 -1.5707</pose>
        </sensor>
        <sensor name='front_camera_sensor' type='camera'>
          <update_rate>30</update_rate>
          <always_on>0</always_on>
          <visualize>0</visualize>
          <camera name='front_camera'>
            <horizontal_fov>2.0944</horizontal_fov>
            <image>
              <width>1280</width>
              <height>1024</height>
              <format>R8G8B8</format>
            </image>
            <clip>
              <near>0.02</near>
              <far>300</far>
            </clip>
            <noise>
              <type>gaussian</type>
              <mean>0</mean>
              <stddev>0.007</stddev>
            </noise>
          </camera>
          <plugin name='front_camera_controller' filename='libgazebo_ros_camera.so'>
            <ros>
              <namespace>prius</namespace>
            </ros>
            <camera_name>/prius/front_camera</camera_name>
            <frame_name>front_camera_link_optical</frame_name>
            <hack_baseline>0.07</hack_baseline>
          </plugin>
          <pose>0 -0.9 1.1 0 0 -1.5707</pose>
        </sensor>
        <self_collide>0</self_collide>
        <enable_wind>0</enable_wind>
        <kinematic>0</kinematic>
      </link>
      <joint name='front_left_steer_joint' type='revolute'>
        <pose relative_to='chassis'>0.767 -1.41 0.3 0 -0 0</pose>
        <parent>chassis</parent>
        <child>fl_axle</child>
        <axis>
          <xyz>0 0 1</xyz>
          <limit>
            <effort>1e+07</effort>
            <velocity>1e+06</velocity>
            <lower>-1e+16</lower>
            <upper>1e+16</upper>
          </limit>
          <dynamics>
            <spring_reference>0</spring_reference>
            <spring_stiffness>0</spring_stiffness>
          </dynamics>
        </axis>
      </joint>
      <link name='fl_axle'>
        <pose relative_to='front_left_steer_joint'>0 0 0 0 -0 0</pose>
        <inertial>
          <pose>0 0 0 0 -0 0</pose>
          <mass>1</mass>
          <inertia>
            <ixx>0.004</ixx>
            <ixy>0</ixy>
            <ixz>0</ixz>
            <iyy>0.004</iyy>
            <iyz>0</iyz>
            <izz>0.004</izz>
          </inertia>
        </inertial>
        <self_collide>0</self_collide>
        <enable_wind>0</enable_wind>
        <kinematic>0</kinematic>
      </link>
      <joint name='front_left_wheel_joint' type='revolute'>
        <pose relative_to='fl_axle'>0 0 0 0 -0 0</pose>
        <parent>fl_axle</parent>
        <child>front_left_wheel</child>
        <axis>
          <xyz>1 0 0</xyz>
          <limit>
            <lower>-1e+16</lower>
            <upper>1e+16</upper>
          </limit>
          <dynamics>
            <spring_reference>0</spring_reference>
            <spring_stiffness>0</spring_stiffness>
          </dynamics>
        </axis>
      </joint>
      <link name='front_left_wheel'>
        <pose relative_to='front_left_wheel_joint'>0 0 0 0 -0 0</pose>
        <inertial>
          <pose>0 0 0 0 -0 0</pose>
          <mass>11</mass>
          <inertia>
            <ixx>0.586312</ixx>
            <ixy>0</ixy>
            <ixz>0</ixz>
            <iyy>0.335529</iyy>
            <iyz>0</iyz>
            <izz>0.335529</izz>
          </inertia>
        </inertial>
        <collision name='front_left_wheel_collision_collision'>
          <pose>0 0 0 0 -0 0</pose>
          <geometry>
            <sphere>
              <radius>0.31265</radius>
            </sphere>
          </geometry>
          <surface>
            <contact>
              <ode>
                <kp>1e+08</kp>
                <min_depth>0.005</min_depth>
              </ode>
            </contact>
            <friction>
              <ode>
                <mu>0.9</mu>
                <mu2>0.9</mu2>
              </ode>
              <torsional>
                <ode/>
              </torsional>
            </friction>
            <bounce/>
          </surface>
          <max_contacts>10</max_contacts>
        </collision>
        <visual name='front_left_wheel_visual'>
          <pose>0 0 0 0 -0 0</pose>
          <geometry>
            <mesh>
              <scale>0.01 0.01 0.01</scale>
              <uri>model://prius_description/meshes/wheel.obj</uri>
            </mesh>
          </geometry>
        </visual>
        <self_collide>0</self_collide>
        <enable_wind>0</enable_wind>
        <kinematic>0</kinematic>
      </link>
      <joint name='front_right_steer_joint' type='revolute'>
        <pose relative_to='chassis'>-0.767 -1.41 0.3 0 -0 0</pose>
        <parent>chassis</parent>
        <child>fr_axle</child>
        <axis>
          <xyz>0 0 1</xyz>
          <limit>
            <effort>1e+07</effort>
            <velocity>1e+06</velocity>
            <lower>-1e+16</lower>
            <upper>1e+16</upper>
          </limit>
          <dynamics>
            <spring_reference>0</spring_reference>
            <spring_stiffness>0</spring_stiffness>
          </dynamics>
        </axis>
      </joint>
      <link name='fr_axle'>
        <pose relative_to='front_right_steer_joint'>0 0 0 0 -0 0</pose>
        <inertial>
          <pose>0 0 0 0 -0 0</pose>
          <mass>1</mass>
          <inertia>
            <ixx>0.004</ixx>
            <ixy>0</ixy>
            <ixz>0</ixz>
            <iyy>0.004</iyy>
            <iyz>0</iyz>
            <izz>0.004</izz>
          </inertia>
        </inertial>
        <self_collide>0</self_collide>
        <enable_wind>0</enable_wind>
        <kinematic>0</kinematic>
      </link>
      <joint name='front_right_wheel_joint' type='revolute'>
        <pose relative_to='fr_axle'>0 0 0 0 -0 0</pose>
        <parent>fr_axle</parent>
        <child>front_right_wheel</child>
        <axis>
          <xyz>1 0 0</xyz>
          <limit>
            <lower>-1e+16</lower>
            <upper>1e+16</upper>
          </limit>
          <dynamics>
            <spring_reference>0</spring_reference>
            <spring_stiffness>0</spring_stiffness>
          </dynamics>
        </axis>
      </joint>
      <link name='front_right_wheel'>
        <pose relative_to='front_right_wheel_joint'>0 0 0 0 -0 0</pose>
        <inertial>
          <pose>0 0 0 0 -0 0</pose>
          <mass>11</mass>
          <inertia>
            <ixx>0.586312</ixx>
            <ixy>0</ixy>
            <ixz>0</ixz>
            <iyy>0.335529</iyy>
            <iyz>0</iyz>
            <izz>0.335529</izz>
          </inertia>
        </inertial>
        <collision name='front_right_wheel_collision_collision'>
          <pose>0 0 0 0 -0 0</pose>
          <geometry>
            <sphere>
              <radius>0.31265</radius>
            </sphere>
          </geometry>
          <surface>
            <contact>
              <ode>
                <kp>1e+08</kp>
                <min_depth>0.005</min_depth>
              </ode>
            </contact>
            <friction>
              <ode>
                <mu>0.9</mu>
                <mu2>0.9</mu2>
              </ode>
              <torsional>
                <ode/>
              </torsional>
            </friction>
            <bounce/>
          </surface>
          <max_contacts>10</max_contacts>
        </collision>
        <visual name='front_right_wheel_visual'>
          <pose>0 0 0 0 -0 0</pose>
          <geometry>
            <mesh>
              <scale>0.01 0.01 0.01</scale>
              <uri>model://prius_description/meshes/wheel.obj</uri>
            </mesh>
          </geometry>
        </visual>
        <self_collide>0</self_collide>
        <enable_wind>0</enable_wind>
        <kinematic>0</kinematic>
      </link>
      <joint name='rear_left_wheel_joint' type='revolute'>
        <pose relative_to='chassis'>0.793 1.45 0.3 0 -0 0</pose>
        <parent>chassis</parent>
        <child>rear_left_wheel</child>
        <axis>
          <xyz>1 0 0</xyz>
          <limit>
            <lower>-1e+16</lower>
            <upper>1e+16</upper>
          </limit>
          <dynamics>
            <spring_reference>0</spring_reference>
            <spring_stiffness>0</spring_stiffness>
          </dynamics>
        </axis>
      </joint>
      <link name='rear_left_wheel'>
        <pose relative_to='rear_left_wheel_joint'>0 0 0 0 -0 0</pose>
        <inertial>
          <pose>0 0 0 0 -0 0</pose>
          <mass>11</mass>
          <inertia>
            <ixx>0.586312</ixx>
            <ixy>0</ixy>
            <ixz>0</ixz>
            <iyy>0.335529</iyy>
            <iyz>0</iyz>
            <izz>0.335529</izz>
          </inertia>
        </inertial>
        <collision name='rear_left_wheel_collision_collision'>
          <pose>0 0 0 0 -0 0</pose>
          <geometry>
            <sphere>
              <radius>0.31265</radius>
            </sphere>
          </geometry>
          <surface>
            <contact>
              <ode>
                <kp>1e+08</kp>
                <min_depth>0.005</min_depth>
              </ode>
            </contact>
            <friction>
              <ode>
                <mu>0.9</mu>
                <mu2>0.9</mu2>
              </ode>
              <torsional>
                <ode/>
              </torsional>
            </friction>
            <bounce/>
          </surface>
          <max_contacts>10</max_contacts>
        </collision>
        <visual name='rear_left_wheel_visual'>
          <pose>0 0 0 0 -0 0</pose>
          <geometry>
            <mesh>
              <scale>0.01 0.01 0.01</scale>
              <uri>model://prius_description/meshes/wheel.obj</uri>
            </mesh>
          </geometry>
        </visual>
        <self_collide>0</self_collide>
        <enable_wind>0</enable_wind>
        <kinematic>0</kinematic>
      </link>
      <joint name='rear_right_wheel_joint' type='revolute'>
        <pose relative_to='chassis'>-0.793 1.45 0.3 0 -0 0</pose>
        <parent>chassis</parent>
        <child>rear_right_wheel</child>
        <axis>
          <xyz>1 0 0</xyz>
          <limit>
            <lower>-1e+16</lower>
            <upper>1e+16</upper>
          </limit>
          <dynamics>
            <spring_reference>0</spring_reference>
            <spring_stiffness>0</spring_stiffness>
          </dynamics>
        </axis>
      </joint>
      <link name='rear_right_wheel'>
        <pose relative_to='rear_right_wheel_joint'>0 0 0 0 -0 0</pose>
        <inertial>
          <pose>0 0 0 0 -0 0</pose>
          <mass>11</mass>
          <inertia>
            <ixx>0.586312</ixx>
            <ixy>0</ixy>
            <ixz>0</ixz>
            <iyy>0.335529</iyy>
            <iyz>0</iyz>
            <izz>0.335529</izz>
          </inertia>
        </inertial>
        <collision name='rear_right_wheel_collision_collision'>
          <pose>0 0 0 0 -0 0</pose>
          <geometry>
            <sphere>
              <radius>0.31265</radius>
            </sphere>
          </geometry>
          <surface>
            <contact>
              <ode>
                <kp>1e+08</kp>
                <min_depth>0.005</min_depth>
              </ode>
            </contact>
            <friction>
              <ode>
                <mu>0.9</mu>
                <mu2>0.9</mu2>
              </ode>
              <torsional>
                <ode/>
              </torsional>
            </friction>
            <bounce/>
          </surface>
          <max_contacts>10</max_contacts>
        </collision>
        <visual name='rear_right_wheel_visual'>
          <pose>0 0 0 0 -0 0</pose>
          <geometry>
            <mesh>
              <scale>0.01 0.01 0.01</scale>
              <uri>model://prius_description/meshes/wheel.obj</uri>
            </mesh>
          </geometry>
        </visual>
        <self_collide>0</self_collide>
        <enable_wind>0</enable_wind>
        <kinematic>0</kinematic>
      </link>
      <joint name='steering_joint' type='revolute'>
        <pose relative_to='chassis'>0.357734 -0.627868 0.988243 -1.3021 0 0</pose>
        <parent>chassis</parent>
        <child>steering_wheel</child>
        <axis>
          <xyz>0 0 1</xyz>
          <limit>
            <effort>1e+07</effort>
            <velocity>1e+06</velocity>
            <lower>-1e+16</lower>
            <upper>1e+16</upper>
          </limit>
          <dynamics>
            <spring_reference>0</spring_reference>
            <spring_stiffness>0</spring_stiffness>
          </dynamics>
        </axis>
      </joint>
      <link name='steering_wheel'>
        <pose relative_to='steering_joint'>0 0 0 0 -0 0</pose>
        <inertial>
          <pose>0 0 0 0 -0 0</pose>
          <mass>1</mass>
          <inertia>
            <ixx>0.145833</ixx>
            <ixy>0</ixy>
            <ixz>0</ixz>
            <iyy>0.145833</iyy>
            <iyz>0</iyz>
            <izz>0.125</izz>
          </inertia>
        </inertial>
        <visual name='steering_wheel_visual'>
          <pose>0 0 0 1.3021 -0 0</pose>
          <geometry>
            <mesh>
              <scale>0.01 0.01 0.01</scale>
              <uri>model://prius_description/meshes/steering_wheel.obj</uri>
            </mesh>
          </geometry>
        </visual>
        <self_collide>0</self_collide>
        <enable_wind>0</enable_wind>
        <kinematic>0</kinematic>
      </link>
      <plugin name='joint_states' filename='libgazebo_ros_joint_state_publisher.so'>
        <ros>
          <namespace>prius</namespace>
          <remapping>~/out:=joint_states</remapping>
        </ros>
        <update_rate>30</update_rate>
        <joint_name>steering_joint</joint_name>
        <joint_name>front_left_steer_joint</joint_name>
        <joint_name>front_right_steer_joint</joint_name>
        <joint_name>front_left_wheel_joint</joint_name>
        <joint_name>front_right_wheel_joint</joint_name>
        <joint_name>rear_left_wheel_joint</joint_name>
        <joint_name>rear_right_wheel_joint</joint_name>
      </plugin>
      <plugin name='pruis_hybrid_drive' filename='libPriusHybridPlugin.so'>
        <ros>
          <namespace>prius</namespace>
          <remapping>prius:=control</remapping>
        </ros>
        <chassis>chassis</chassis>
        <front_left_wheel>front_left_wheel_joint</front_left_wheel>
        <front_right_wheel>front_right_wheel_joint</front_right_wheel>
        <front_left_wheel_steering>front_left_steer_joint</front_left_wheel_steering>
        <front_right_wheel_steering>front_right_steer_joint</front_right_wheel_steering>
        <back_left_wheel>rear_left_wheel_joint</back_left_wheel>
        <back_right_wheel>rear_right_wheel_joint</back_right_wheel>
        <steering_wheel>steering_joint</steering_wheel>
        <chassis_aero_force_gain>0.63045</chassis_aero_force_gain>
        <front_torque>859.4004393000001</front_torque>
        <back_torque>0</back_torque>
        <front_brake_torque>1031.28052716</front_brake_torque>
        <back_brake_torque>687.5203514400001</back_brake_torque>
        <battery_charge_watt_hours>291</battery_charge_watt_hours>
        <battery_discharge_watt_hours>214</battery_discharge_watt_hours>
        <gas_efficiency>0.371</gas_efficiency>
        <min_gas_flow>8.981854013171626e-05</min_gas_flow>
        <max_speed>37.998337013956565</max_speed>
        <max_steer>0.6458</max_steer>
        <flwheel_steering_p_gain>1e4</flwheel_steering_p_gain>
        <frwheel_steering_p_gain>1e4</frwheel_steering_p_gain>
        <flwheel_steering_i_gain>0</flwheel_steering_i_gain>
        <frwheel_steering_i_gain>0</frwheel_steering_i_gain>
        <flwheel_steering_d_gain>3e2</flwheel_steering_d_gain>
        <frwheel_steering_d_gain>3e2</frwheel_steering_d_gain>
      </plugin>
      <plugin name='p3d' filename='libgazebo_ros_p3d.so'>
        <ros>
          <namespace>prius</namespace>
          <argument>odom:=ground_truth</argument>
        </ros>
        <body_name>chassis</body_name>
        <topic_name>base_pose_ground_truth</topic_name>
        <frame_name>world</frame_name>
        <gaussian_noise>0.01</gaussian_noise>
      </plugin>
      <frame name='dummy_joint' attached_to='dummy'>
        <pose>0 0 0 0 -0 0</pose>
      </frame>
      <frame name='base_link' attached_to='dummy_joint'/>
      <frame name='center_laser_joint' attached_to='chassis'>
        <pose>0 0.4 1.8 0 0 -1.5707</pose>
      </frame>
      <frame name='center_laser_link' attached_to='center_laser_joint'/>
      <frame name='front_camera_optical_joint' attached_to='front_camera_link'>
        <pose>0 0 0 -1.5707 0 -1.5707</pose>
      </frame>
      <frame name='front_camera_link_optical' attached_to='front_camera_optical_joint'/>
      <frame name='front_camera_joint' attached_to='chassis'>
        <pose>0 -0.9 1.1 0 0 -1.5707</pose>
      </frame>
      <frame name='front_camera_link' attached_to='front_camera_joint'/>
      <pose>1.5 -45 0.058 0 -0 1.5708</pose>
      <update_rate>30.0</update_rate>
    </model>
  </world>
</sdf>
